{"name": "Проверка получения ошибки под неверным логином и паролем", "status": "passed", "start": 1713972027274, "stop": 1713972027540, "uuid": "c2e11b8c-bc8e-4db8-a113-e35c3d2a4d61", "historyId": "5fd5da3b3ca8fdf751feb802572e5b42", "testCaseId": "5fd5da3b3ca8fdf751feb802572e5b42", "fullName": "tests.test_login.TestLogin#test_login_error", "labels": [{"name": "parentSuite", "value": "tests"}, {"name": "suite", "value": "test_login"}, {"name": "subSuite", "value": "TestLogin"}, {"name": "host", "value": "DESKTOP-TQ0O0FL"}, {"name": "thread", "value": "3408-MainThread"}, {"name": "framework", "value": "pytest"}, {"name": "language", "value": "cpython3"}, {"name": "package", "value": "tests.test_login"}]}